Workbook
Name Slicer_Months__Order_Date: #N/A
Name Slicer_Warehouse: #N/A
Name Slicer_Years__Order_Date: #N/A

Sheet Pivot
B2: PRIMARY KPIs
B3: Count of Order_ID | C3: Sum of Quantity | D3: Sum of Total_Cost | E3: Average of Delay_Days
B4: 103 | C4: 9283 | D4: 542537.51 | E4: 14.106796
B10: Monthly Order Trends
B11: Count of Order_ID | C11: Column Labels | G11: Count of Order_ID | H11: Column Labels
B12: Row Labels | C12: 2024 | D12: Grand Total | G12: Row Labels | H12: 2024 | I12: Grand Total
B13: Mar | C13: 12 | D13: 12 | G13: Jan | H13: 9 | I13: 9
B14: Apr | C14: 15 | D14: 15 | G14: Feb | H14: 12 | I14: 12
B15: May | C15: 8 | D15: 8 | G15: Mar | H15: 12 | I15: 12
B16: Jun | C16: 7 | D16: 7 | G16: Apr | H16: 15 | I16: 15
B17: Jul | C17: 7 | D17: 7 | G17: May | H17: 8 | I17: 8
B18: Aug | C18: 14 | D18: 14 | G18: Jun | H18: 7 | I18: 7
B19: Sep | C19: 15 | D19: 15 | G19: Jul | H19: 7 | I19: 7
B20: Oct | C20: 16 | D20: 16 | G20: Aug | H20: 14 | I20: 14
B21: Nov | C21: 9 | D21: 9 | G21: Sep | H21: 15 | I21: 15
B22: Grand Total | C22: 103 | D22: 103 | G22: Oct | H22: 16 | I22: 16
G23: Nov | H23: 9 | I23: 9
G24: Dec | H24: 8 | I24: 8
G25: Grand Total | H25: 132 | I25: 132
B27: Orders & QTY by Status
B28: Row Labels | C28: Count of Order_ID | D28: Sum of Quantity
B29: Pending | C29: 36 | D29: 3456
B30: Delivered | C30: 49 | D30: 4143
B31: Cancelled | C31: 18 | D31: 1684
B32: Grand Total | C32: 103 | D32: 9283
B36: Orders by Transport
B37: Row Labels | C37: Count of Order_ID | F37: Row Labels | G37: Count of Order_ID
B38: Air | C38: 39 | F38: Air | G38: 39
B39: Rail | C39: 21 | F39: Rail | G39: 21
B40: Road | C40: 7 | F40: Road | G40: 7
B41: Sea | C41: 36 | F41: Sea | G41: 36
B42: Grand Total | C42: 103 | F42: Grand Total | G42: 103
B46: Order by Warehouses
B47: Row Labels | C47: Count of Order_ID | F47: Row Labels | G47: Count of Order_ID
B48: WH1 | C48: 103 | F48: WH1 | G48: 103
B49: Grand Total | C49: 103 | F49: WH2 | G49: 35
F50: WH3 | G50: 58
F51: Grand Total | G51: 196
B55: Country wise Cost
B56: Row Labels | C56: Sum of Total_Cost | F56: Row Labels | G56: Sum of Total_Cost
...

Sheet Dashboard

Sheet Processing
A1: Total Orders | B1: Total Quantity | C1: Total Cost | D1: Avg Delay Days
A2: =GETPIVOTDATA("Count of Order_ID",Pivot!$B$3) -> 103 | B2: =GETPIVOTDATA("Sum of Quantity",Pivot!$B$3) -> 9283 | C2: =GETPIVOTDATA("Sum of Total_Cost",Pivot!$B$3) -> 542537.51 | D2: =GETPIVOTDATA("Average of Delay_Days",Pivot!$B$3) -> 14.106796
C5: =IFERROR(MATCH(B6,Pivot!B65:B66,0),2) -> 2 | D5: {=INDEX($C$6:$D$6,1,C5)} -> 2024
B6: 2023 | C6: 2023 | D6: 2024 | E6: 2024
A7: Monthly Quantity Trends | B7: QTY | C7: Cursor Q | D7: QTY | E7: Cursor Q
A8: Jan | B8: =IF($C$5=1,GETPIVOTDATA("Sum of Quantity",Pivot!$G$11,"Months (Order_Date)",A8),NA()) -> #N/A | C8: =IF($C$5=1,IFERROR(GETPIVOTDATA("Sum of Quantity",Pivot!$B$11,"Months (Order_Date)",A8),NA()),NA()) -> #N/A | D8: =IF($C$5=1,NA(),GETPIVOTDATA("Sum of Quantity",Pivot!$G$11,"Months (Order_Date)",A8)) -> #REF! | E8: =IF($C$5=1,NA(),IFERROR(GETPIVOTDATA("Sum of Quantity",Pivot!$B$11,"Months (Order_Date)",A8),NA())) -> #N/A
A9: Feb | B9: =IF($C$5=1,GETPIVOTDATA("Sum of Quantity",Pivot!$G$11,"Months (Order_Date)",A9),NA()) -> #N/A | C9: =IF($C$5=1,IFERROR(GETPIVOTDATA("Sum of Quantity",Pivot!$B$11,"Months (Order_Date)",A9),NA()),NA()) -> #N/A | D9: =IF($C$5=1,NA(),GETPIVOTDATA("Sum of Quantity",Pivot!$G$11,"Months (Order_Date)",A9)) -> #REF! | E9: =IF($C$5=1,NA(),IFERROR(GETPIVOTDATA("Sum of Quantity",Pivot!$B$11,"Months (Order_Date)",A9),NA())) -> #N/A
A10: Mar | B10: =IF($C$5=1,GETPIVOTDATA("Sum of Quantity",Pivot!$G$11,"Months (Order_Date)",A10),NA()) -> #N/A | C10: =IF($C$5=1,IFERROR(GETPIVOTDATA("Sum of Quantity",Pivot!$B$11,"Months (Order_Date)",A10),NA()),NA()) -> #N/A | D10: =IF($C$5=1,NA(),GETPIVOTDATA("Sum of Quantity",Pivot!$G$11,"Months (Order_Date)",A10)) -> #REF! | E10: =IF($C$5=1,NA(),IFERROR(GETPIVOTDATA("Sum of Quantity",Pivot!$B$11,"Months (Order_Date)",A10),NA())) -> #N/A
A11: Apr | B11: =IF($C$5=1,GETPIVOTDATA("Sum of Quantity",Pivot!$G$11,"Months (Order_Date)",A11),NA()) -> #N/A | C11: =IF($C$5=1,IFERROR(GETPIVOTDATA("Sum of Quantity",Pivot!$B$11,"Months (Order_Date)",A11),NA()),NA()) -> #N/A | D11: =IF($C$5=1,NA(),GETPIVOTDATA("Sum of Quantity",Pivot!$G$11,"Months (Order_Date)",A11)) -> #REF! | E11: =IF($C$5=1,NA(),IFERROR(GETPIVOTDATA("Sum of Quantity",Pivot!$B$11,"Months (Order_Date)",A11),NA())) -> #N/A
A12: May | B12: =IF($C$5=1,GETPIVOTDATA("Sum of Quantity",Pivot!$G$11,"Months (Order_Date)",A12),NA()) -> #N/A | C12: =IF($C$5=1,IFERROR(GETPIVOTDATA("Sum of Quantity",Pivot!$B$11,"Months (Order_Date)",A12),NA()),NA()) -> #N/A | D12: =IF($C$5=1,NA(),GETPIVOTDATA("Sum of Quantity",Pivot!$G$11,"Months (Order_Date)",A12)) -> #REF! | E12: =IF($C$5=1,NA(),IFERROR(GETPIVOTDATA("Sum of Quantity",Pivot!$B$11,"Months (Order_Date)",A12),NA())) -> #N/A
A13: Jun | B13: =IF($C$5=1,GETPIVOTDATA("Sum of Quantity",Pivot!$G$11,"Months (Order_Date)",A13),NA()) -> #N/A | C13: =IF($C$5=1,IFERROR(GETPIVOTDATA("Sum of Quantity",Pivot!$B$11,"Months (Order_Date)",A13),NA()),NA()) -> #N/A | D13: =IF($C$5=1,NA(),GETPIVOTDATA("Sum of Quantity",Pivot!$G$11,"Months (Order_Date)",A13)) -> #REF! | E13: =IF($C$5=1,NA(),IFERROR(GETPIVOTDATA("Sum of Quantity",Pivot!$B$11,"Months (Order_Date)",A13),NA())) -> #N/A
A14: Jul | B14: =IF($C$5=1,GETPIVOTDATA("Sum of Quantity",Pivot!$G$11,"Months (Order_Date)",A14),NA()) -> #N/A | C14: =IF($C$5=1,IFERROR(GETPIVOTDATA("Sum of Quantity",Pivot!$B$11,"Months (Order_Date)",A14),NA()),NA()) -> #N/A | D14: =IF($C$5=1,NA(),GETPIVOTDATA("Sum of Quantity",Pivot!$G$11,"Months (Order_Date)",A14)) -> #REF! | E14: =IF($C$5=1,NA(),IFERROR(GETPIVOTDATA("Sum of Quantity",Pivot!$B$11,"Months (Order_Date)",A14),NA())) -> #N/A
A15: Aug | B15: =IF($C$5=1,GETPIVOTDATA("Sum of Quantity",Pivot!$G$11,"Months (Order_Date)",A15),NA()) -> #N/A | C15: =IF($C$5=1,IFERROR(GETPIVOTDATA("Sum of Quantity",Pivot!$B$11,"Months (Order_Date)",A15),NA()),NA()) -> #N/A | D15: =IF($C$5=1,NA(),GETPIVOTDATA("Sum of Quantity",Pivot!$G$11,"Months (Order_Date)",A15)) -> #REF! | E15: =IF($C$5=1,NA(),IFERROR(GETPIVOTDATA("Sum of Quantity",Pivot!$B$11,"Months (Order_Date)",A15),NA())) -> #N/A
A16: Sep | B16: =IF($C$5=1,GETPIVOTDATA("Sum of Quantity",Pivot!$G$11,"Months (Order_Date)",A16),NA()) -> #N/A | C16: =IF($C$5=1,IFERROR(GETPIVOTDATA("Sum of Quantity",Pivot!$B$11,"Months (Order_Date)",A16),NA()),NA()) -> #N/A | D16: =IF($C$5=1,NA(),GETPIVOTDATA("Sum of Quantity",Pivot!$G$11,"Months (Order_Date)",A16)) -> #REF! | E16: =IF($C$5=1,NA(),IFERROR(GETPIVOTDATA("Sum of Quantity",Pivot!$B$11,"Months (Order_Date)",A16),NA())) -> #N/A
A17: Oct | B17: =IF($C$5=1,GETPIVOTDATA("Sum of Quantity",Pivot!$G$11,"Months (Order_Date)",A17),NA()) -> #N/A | C17: =IF($C$5=1,IFERROR(GETPIVOTDATA("Sum of Quantity",Pivot!$B$11,"Months (Order_Date)",A17),NA()),NA()) -> #N/A | D17: =IF($C$5=1,NA(),GETPIVOTDATA("Sum of Quantity",Pivot!$G$11,"Months (Order_Date)",A17)) -> #REF! | E17: =IF($C$5=1,NA(),IFERROR(GETPIVOTDATA("Sum of Quantity",Pivot!$B$11,"Months (Order_Date)",A17),NA())) -> #N/A
A18: Nov | B18: =IF($C$5=1,GETPIVOTDATA("Sum of Quantity",Pivot!$G$11,"Months (Order_Date)",A18),NA()) -> #N/A | C18: =IF($C$5=1,IFERROR(GETPIVOTDATA("Sum of Quantity",Pivot!$B$11,"Months (Order_Date)",A18),NA()),NA()) -> #N/A | D18: =IF($C$5=1,NA(),GETPIVOTDATA("Sum of Quantity",Pivot!$G$11,"Months (Order_Date)",A18)) -> #REF! | E18: =IF($C$5=1,NA(),IFERROR(GETPIVOTDATA("Sum of Quantity",Pivot!$B$11,"Months (Order_Date)",A18),NA())) -> #N/A
A19: Dec | B19: =IF($C$5=1,GETPIVOTDATA("Sum of Quantity",Pivot!$G$11,"Months (Order_Date)",A19),NA()) -> #N/A | C19: =IF($C$5=1,IFERROR(GETPIVOTDATA("Sum of Quantity",Pivot!$B$11,"Months (Order_Date)",A19),NA()),NA()) -> #N/A | D19: =IF($C$5=1,NA(),GETPIVOTDATA("Sum of Quantity",Pivot!$G$11,"Months (Order_Date)",A19)) -> #REF! | E19: =IF($C$5=1,NA(),IFERROR(GETPIVOTDATA("Sum of Quantity",Pivot!$B$11,"Months (Order_Date)",A19),NA())) -> #N/A
C20: {=SUM(IFERROR(INDEX(($C$8:$C$19,$E$8:$E$19),0,1,$C$5),""))} -> 0 | D20: =IF(D22,0,1) -> 1
D21: =IF($D$22,1,0) -> 0
D22: FALSE | E22: 1.05
A23: Monthly Quantity Trends | B23: 2024 | C23: Cursor 2024 | D23: 2023 | E23: indent | F23: 2023-Fill
A24: Jan | B24: =GETPIVOTDATA("Quantity",Pivot!$H$70,"Months (Order_Date)",$A24,"Years (Order_Date)",B$23) -> 952 | C24: =IFERROR(GETPIVOTDATA("Quantity",Pivot!$B$70,"Months (Order_Date)",$A24,"Years (Order_Date)",B$23),NA()) -> #N/A | D24: =IF($D$22,GETPIVOTDATA("Quantity",Pivot!$H$70,"Months (Order_Date)",$A24,"Years (Order_Date)",D$23),NA()) -> #N/A | E24: =C24*$E$22 -> #N/A | F24: =D24 -> #N/A
A25: Feb | B25: =GETPIVOTDATA("Quantity",Pivot!$H$70,"Months (Order_Date)",$A25,"Years (Order_Date)",B$23) -> 1091 | C25: =IFERROR(GETPIVOTDATA("Quantity",Pivot!$B$70,"Months (Order_Date)",$A25,"Years (Order_Date)",B$23),NA()) -> #N/A | D25: =IF($D$22,GETPIVOTDATA("Quantity",Pivot!$H$70,"Months (Order_Date)",$A25,"Years (Order_Date)",D$23),NA()) -> #N/A | E25: =C25*$E$22 -> #N/A | F25: =D25 -> #N/A
A26: Mar | B26: =GETPIVOTDATA("Quantity",Pivot!$H$70,"Months (Order_Date)",$A26,"Years (Order_Date)",B$23) -> 1281 | C26: =IFERROR(GETPIVOTDATA("Quantity",Pivot!$B$70,"Months (Order_Date)",$A26,"Years (Order_Date)",B$23),NA()) -> 1281 | D26: =IF($D$22,GETPIVOTDATA("Quantity",Pivot!$H$70,"Months (Order_Date)",$A26,"Years (Order_Date)",D$23),NA()) -> #N/A | E26: =C26*$E$22 -> 1345.05 | F26: =D26 -> #N/A
A27: Apr | B27: =GETPIVOTDATA("Quantity",Pivot!$H$70,"Months (Order_Date)",$A27,"Years (Order_Date)",B$23) -> 920 | C27: =IFERROR(GETPIVOTDATA("Quantity",Pivot!$B$70,"Months (Order_Date)",$A27,"Years (Order_Date)",B$23),NA()) -> 920 | D27: =IF($D$22,GETPIVOTDATA("Quantity",Pivot!$H$70,"Months (Order_Date)",$A27,"Years (Order_Date)",D$23),NA()) -> #N/A | E27: =C27*$E$22 -> 966 | F27: =D27 -> #N/A
A28: May | B28: =GETPIVOTDATA("Quantity",Pivot!$H$70,"Months (Order_Date)",$A28,"Years (Order_Date)",B$23) -> 615 | C28: =IFERROR(GETPIVOTDATA("Quantity",Pivot!$B$70,"Months (Order_Date)",$A28,"Years (Order_Date)",B$23),NA()) -> 615 | D28: =IF($D$22,GETPIVOTDATA("Quantity",Pivot!$H$70,"Months (Order_Date)",$A28,"Years (Order_Date)",D$23),NA()) -> #N/A | E28: =C28*$E$22 -> 645.75 | F28: =D28 -> #N/A
A29: Jun | B29: =GETPIVOTDATA("Quantity",Pivot!$H$70,"Months (Order_Date)",$A29,"Years (Order_Date)",B$23) -> 694 | C29: =IFERROR(GETPIVOTDATA("Quantity",Pivot!$B$70,"Months (Order_Date)",$A29,"Years (Order_Date)",B$23),NA()) -> 694 | D29: =IF($D$22,GETPIVOTDATA("Quantity",Pivot!$H$70,"Months (Order_Date)",$A29,"Years (Order_Date)",D$23),NA()) -> #N/A | E29: =C29*$E$22 -> 728.7 | F29: =D29 -> #N/A
A30: Jul | B30: =GETPIVOTDATA("Quantity",Pivot!$H$70,"Months (Order_Date)",$A30,"Years (Order_Date)",B$23) -> 565 | C30: =IFERROR(GETPIVOTDATA("Quantity",Pivot!$B$70,"Months (Order_Date)",$A30,"Years (Order_Date)",B$23),NA()) -> 565 | D30: =IF($D$22,GETPIVOTDATA("Quantity",Pivot!$H$70,"Months (Order_Date)",$A30,"Years (Order_Date)",D$23),NA()) -> #N/A | E30: =C30*$E$22 -> 593.25 | F30: =D30 -> #N/A
A31: Aug | B31: =GETPIVOTDATA("Quantity",Pivot!$H$70,"Months (Order_Date)",$A31,"Years (Order_Date)",B$23) -> 1288 | C31: =IFERROR(GETPIVOTDATA("Quantity",Pivot!$B$70,"Months (Order_Date)",$A31,"Years (Order_Date)",B$23),NA()) -> 1288 | D31: =IF($D$22,GETPIVOTDATA("Quantity",Pivot!$H$70,"Months (Order_Date)",$A31,"Years (Order_Date)",D$23),NA()) -> #N/A | E31: =C31*$E$22 -> 1352.4 | F31: =D31 -> #N/A
A32: Sep | B32: =GETPIVOTDATA("Quantity",Pivot!$H$70,"Months (Order_Date)",$A32,"Years (Order_Date)",B$23) -> 1459 | C32: =IFERROR(GETPIVOTDATA("Quantity",Pivot!$B$70,"Months (Order_Date)",$A32,"Years (Order_Date)",B$23),NA()) -> 1459 | D32: =IF($D$22,GETPIVOTDATA("Quantity",Pivot!$H$70,"Months (Order_Date)",$A32,"Years (Order_Date)",D$23),NA()) -> #N/A | E32: =C32*$E$22 -> 1531.95 | F32: =D32 -> #N/A
A33: Oct | B33: =GETPIVOTDATA("Quantity",Pivot!$H$70,"Months (Order_Date)",$A33,"Years (Order_Date)",B$23) -> 1618 | C33: =IFERROR(GETPIVOTDATA("Quantity",Pivot!$B$70,"Months (Order_Date)",$A33,"Years (Order_Date)",B$23),NA()) -> 1618 | D33: =IF($D$22,GETPIVOTDATA("Quantity",Pivot!$H$70,"Months (Order_Date)",$A33,"Years (Order_Date)",D$23),NA()) -> #N/A | E33: =C33*$E$22 -> 1698.9 | F33: =D33 -> #N/A
A34: Nov | B34: =GETPIVOTDATA("Quantity",Pivot!$H$70,"Months (Order_Date)",$A34,"Years (Order_Date)",B$23) -> 843 | C34: =IFERROR(GETPIVOTDATA("Quantity",Pivot!$B$70,"Months (Order_Date)",$A34,"Years (Order_Date)",B$23),NA()) -> 843 | D34: =IF($D$22,GETPIVOTDATA("Quantity",Pivot!$H$70,"Months (Order_Date)",$A34,"Years (Order_Date)",D$23),NA()) -> #N/A | E34: =C34*$E$22 -> 885.15 | F34: =D34 -> #N/A
A35: Dec | B35: =GETPIVOTDATA("Quantity",Pivot!$H$70,"Months (Order_Date)",$A35,"Years (Order_Date)",B$23) -> 657 | C35: =IFERROR(GETPIVOTDATA("Quantity",Pivot!$B$70,"Months (Order_Date)",$A35,"Years (Order_Date)",B$23),NA()) -> #N/A | D35: =IF($D$22,GETPIVOTDATA("Quantity",Pivot!$H$70,"Months (Order_Date)",$A35,"Years (Order_Date)",D$23),NA()) -> #N/A | E35: =C35*$E$22 -> #N/A | F35: =D35 -> #N/A
C36: =SUMIF(C24:C35,">0") -> 9283 | D36: =IF($D$22,SUMIF(D24:D35,">0"),"")
D37: =IF(D36<>"",2023,"")
A39: Country by Total Cost | B39: Value | C39: % | D39: percetage %
A40: India | B40: =GETPIVOTDATA("Total_Cost",Pivot!$F$56,"Country",A40) -> 162070.26 | C40: =B40/MAX($B$40:$B$43) -> 0.68257894 | D40: =B40/$B$44 -> 0.29872637 | E40: =1-D40 -> 0.70127363
A41: Germany | B41: =GETPIVOTDATA("Total_Cost",Pivot!$F$56,"Country",A41) -> 237438.12 | C41: =B41/MAX($B$40:$B$43) -> 1 | D41: =B41/$B$44 -> 0.43764369 | E41: =1-D41 -> 0.56235631
A42: USA | B42: =GETPIVOTDATA("Total_Cost",Pivot!$F$56,"Country",A42) -> 72757.67 | C42: =B42/MAX($B$40:$B$43) -> 0.30642792 | D42: =B42/$B$44 -> 0.13410625 | E42: =1-D42 -> 0.86589375
A43: China | B43: =GETPIVOTDATA("Total_Cost",Pivot!$F$56,"Country",A43) -> 70271.46 | C43: =B43/MAX($B$40:$B$43) -> 0.29595694 | D43: =B43/$B$44 -> 0.12952369 | E43: =1-D43 -> 0.87047631
...

Sheet Operations

Sheet Dataset
B5: Order_ID | C5: Product | D5: Category | E5: Supplier | F5: Country | G5: Order_Date | H5: Ship_Date | I5: Delivery_Date | J5: Quantity | K5: Unit_Price | L5: Total_Cost | M5: Warehouse | N5: Transport_Mode | O5: Status | P5: Delay_Days
B6: ORD1001 | C6: Tool D | D6: Electronics | E6: Supplierx | F6: China | G6: 45071 | H6: 45204 | I6: 45148 | J6: 311 | K6: 67552.31 | L6: 1946.57 | M6: WH1 | N6: Sea | O6: Delivered | P6: 18
B7: ORD1002 | C7: Gadget C | D7: Hardware | E7: Supplierz | F7: Germany | G7: 45464 | H7: 45159 | I7: 45120 | J7: 328 | K7: 6376.32 | L7: 1303.72 | M7: WH2 | N7: Sea | O7: Delivered | P7: 20
B8: ORD1003 | C8: Gadget C | D8: Hardware | E8: Supplierx | F8: USA | G8: 45574 | H8: 45293 | I8: 45347 | J8: 684 | K8: 166239.36 | L8: 4262.18 | M8: WH1 | N8: Rail | O8: Pending | P8: 7
B9: ORD1004 | C9: Gadget C | D9: Hardware | E9: Supplierx | F9: India | G9: 45229 | H9: 45155 | I9: 45605 | J9: 210 | K9: 69909 | L9: 7763.68 | M9: WH1 | N9: Road | O9: Delivered | P9: 0
B10: ORD1004 | C10: Widget B | D10: Hardware | E10: Supplierx | F10: USA | G10: 45514 | H10: 45578 | I10: 45622 | J10: 72 | K10: 4583.52 | L10: 8896.82 | M10: WH1 | N10: Road | O10: Delivered | P10: 27
B11: ORD1006 | C11: Gadget C | D11: Hardware | E11: Supplierz | F11: Germany | G11: 45271 | H11: 45363 | I11: 45476 | J11: 672 | K11: 99456 | L11: 7263.81 | M11: WH1 | N11: Air | O11: Delivered | P11: 16
B12: ORD1007 | C12: Gadget C | D12: Hardware | E12: Supplierz | F12: Germany | G12: 44927 | H12: 45326 | I12: 44971 | J12: 653 | K12: 131860.29 | L12: 2527.64 | M12: WH2 | N12: Air | O12: Delivered | P12: 6
B13: ORD1008 | C13: Gadget C | D13: Hardware | E13: Supplierz | F13: Germany | G13: 45073 | H13: 45138 | I13: 45237 | J13: 499 | K13: 229624.83 | L13: 9029.01 | M13: WH3 | N13: Air | O13: Delivered | P13: 13
B14: ORD1009 | C14: Gadget C | D14: Hardware | E14: Supplierz | F14: China | G14: 45213 | H14: 45318 | I14: 45268 | J14: 571 | K14: 283592.86 | L14: 1738.8 | M14: WH3 | N14: Air | O14: Delivered | P14: 20
B15: ORD1010 | C15: Tool D | D15: Accessories | E15: Supplierz | F15: China | G15: 45580 | H15: 45426 | I15: 45244 | J15: 308 | K15: 8386.84 | L15: 9211.36 | M15: WH1 | N15: Sea | O15: Delivered | P15: 29
B16: ORD1011 | C16: Gadget C | D16: Hardware | E16: Supplierz | F16: USA | G16: 44979 | H16: 45467 | I16: 45005 | J16: 412 | K16: 157260.4 | L16: 9700.77 | M16: WH1 | N16: Sea | O16: Pending | P16: 20
B17: ORD1012 | C17: Widget A | D17: Electronics | E17: Suppliery | F17: India | G17: 45230 | H17: 45490 | I17: 45209 | J17: 536 | K17: 101304 | L17: 6465.22 | M17: WH1 | N17: Air | O17: Pending | P17: 16
... B476: ORD1499 | C476: Tool D | D476: Electronics | E476: Supplierx | F476: USA | G476: 45571 | H476: 45204 | I476: 45077 | J476: 364 | K476: 146506.36 | L476: 1414.63 | M476: WH3 | N476: Air | O476: Delivered | P476: 2

Sheet Insights
